nohup: ignoring input
 
 -------------- worker2@DESKTOP-2OLMUVD v5.4.0 (opalescent)
--- ***** ----- 
-- ******* ---- Linux-5.15.167.4-microsoft-standard-WSL2-x86_64-with-glibc2.29 2025-02-17 00:13:36
- *** --- * --- 
- ** ---------- [config]
- ** ---------- .> app:         fpl_project:0x7f7123ddd640
- ** ---------- .> transport:   redis://localhost:6380/0
- ** ---------- .> results:     redis://localhost:6380/1
- *** --- * --- .> concurrency: 4 (solo)
-- ******* ---- .> task events: OFF (enable -E to monitor tasks in this worker)
--- ***** ----- 
 -------------- [queues]
                .> celery           exchange=celery(direct) key=celery
                

[tasks]
  . fpl.tasks.fetch_fpl_data
  . fpl_project.celery.debug_task

[2025-02-17 00:13:37,210: WARNING/MainProcess] /home/kevo/fpl_env/lib/python3.8/site-packages/celery/worker/consumer/consumer.py:508: CPendingDeprecationWarning: The broker_connection_retry configuration setting will no longer determine
whether broker connection retries are made during startup in Celery 6.0 and above.
If you wish to retain the existing behavior for retrying connections on startup,
you should set broker_connection_retry_on_startup to True.
  warnings.warn(

[2025-02-17 00:13:37,286: INFO/MainProcess] Connected to redis://localhost:6380/0
[2025-02-17 00:13:37,293: WARNING/MainProcess] /home/kevo/fpl_env/lib/python3.8/site-packages/celery/worker/consumer/consumer.py:508: CPendingDeprecationWarning: The broker_connection_retry configuration setting will no longer determine
whether broker connection retries are made during startup in Celery 6.0 and above.
If you wish to retain the existing behavior for retrying connections on startup,
you should set broker_connection_retry_on_startup to True.
  warnings.warn(

[2025-02-17 00:13:37,302: INFO/MainProcess] mingle: searching for neighbors
[2025-02-17 00:13:38,343: INFO/MainProcess] mingle: all alone
[2025-02-17 00:13:38,517: INFO/MainProcess] worker2@DESKTOP-2OLMUVD ready.
[2025-02-17 00:20:00,131: INFO/MainProcess] Task fpl.tasks.fetch_fpl_data[9563316f-7b50-4d2a-8805-2fc436070f88] received
[2025-02-17 00:20:00,364: ERROR/MainProcess] Task fpl.tasks.fetch_fpl_data[9563316f-7b50-4d2a-8805-2fc436070f88] raised unexpected: ModuleNotFoundError("No module named 'requests'")
Traceback (most recent call last):
  File "/home/kevo/fpl_env/lib/python3.8/site-packages/celery/app/trace.py", line 453, in trace_task
    R = retval = fun(*args, **kwargs)
  File "/home/kevo/fpl_env/lib/python3.8/site-packages/celery/app/trace.py", line 736, in __protected_call__
    return self.run(*args, **kwargs)
  File "/mnt/c/Users/ADMIN/fpl_project/fpl/tasks.py", line 6, in fetch_fpl_data
    call_command("fetch_fpl_data")
  File "/home/kevo/fpl_env/lib/python3.8/site-packages/django/core/management/__init__.py", line 118, in call_command
    command = load_command_class(app_name, command_name)
  File "/home/kevo/fpl_env/lib/python3.8/site-packages/django/core/management/__init__.py", line 48, in load_command_class
    module = import_module("%s.management.commands.%s" % (app_name, name))
  File "/usr/lib/python3.8/importlib/__init__.py", line 127, in import_module
    return _bootstrap._gcd_import(name[level:], package, level)
  File "<frozen importlib._bootstrap>", line 1014, in _gcd_import
  File "<frozen importlib._bootstrap>", line 991, in _find_and_load
  File "<frozen importlib._bootstrap>", line 975, in _find_and_load_unlocked
  File "<frozen importlib._bootstrap>", line 671, in _load_unlocked
  File "<frozen importlib._bootstrap_external>", line 848, in exec_module
  File "<frozen importlib._bootstrap>", line 219, in _call_with_frames_removed
  File "/mnt/c/Users/ADMIN/fpl_project/fpl/management/commands/fetch_fpl_data.py", line 1, in <module>
    import requests
ModuleNotFoundError: No module named 'requests'
[2025-02-17 00:20:54,927: INFO/MainProcess] sync with worker1@DESKTOP-2OLMUVD
[2025-02-17 00:20:55,041: INFO/MainProcess] Task fpl.tasks.fetch_fpl_data[cb3bc5d2-76c2-4d85-be50-1390f29f9832] received
[2025-02-17 00:20:55,105: ERROR/MainProcess] Task fpl.tasks.fetch_fpl_data[cb3bc5d2-76c2-4d85-be50-1390f29f9832] raised unexpected: ModuleNotFoundError("No module named 'requests'")
Traceback (most recent call last):
  File "/home/kevo/fpl_env/lib/python3.8/site-packages/celery/app/trace.py", line 453, in trace_task
    R = retval = fun(*args, **kwargs)
  File "/home/kevo/fpl_env/lib/python3.8/site-packages/celery/app/trace.py", line 736, in __protected_call__
    return self.run(*args, **kwargs)
  File "/mnt/c/Users/ADMIN/fpl_project/fpl/tasks.py", line 6, in fetch_fpl_data
    call_command("fetch_fpl_data")
  File "/home/kevo/fpl_env/lib/python3.8/site-packages/django/core/management/__init__.py", line 118, in call_command
    command = load_command_class(app_name, command_name)
  File "/home/kevo/fpl_env/lib/python3.8/site-packages/django/core/management/__init__.py", line 48, in load_command_class
    module = import_module("%s.management.commands.%s" % (app_name, name))
  File "/usr/lib/python3.8/importlib/__init__.py", line 127, in import_module
    return _bootstrap._gcd_import(name[level:], package, level)
  File "<frozen importlib._bootstrap>", line 1014, in _gcd_import
  File "<frozen importlib._bootstrap>", line 991, in _find_and_load
  File "<frozen importlib._bootstrap>", line 975, in _find_and_load_unlocked
  File "<frozen importlib._bootstrap>", line 671, in _load_unlocked
  File "<frozen importlib._bootstrap_external>", line 848, in exec_module
  File "<frozen importlib._bootstrap>", line 219, in _call_with_frames_removed
  File "/mnt/c/Users/ADMIN/fpl_project/fpl/management/commands/fetch_fpl_data.py", line 1, in <module>
    import requests
ModuleNotFoundError: No module named 'requests'
[2025-02-17 00:26:53,075: INFO/MainProcess] missed heartbeat from worker1@DESKTOP-2OLMUVD
[2025-02-17 06:44:32,307: WARNING/MainProcess] Substantial drift from worker1@DESKTOP-2OLMUVD may mean clocks are out of sync.  Current drift is 22659 seconds.  [orig: 2025-02-17 06:44:32.307001 recv: 2025-02-17 00:26:53.073159]
[2025-02-17 06:50:00,079: INFO/MainProcess] Task fpl.tasks.fetch_fpl_data[a6c2b6a4-7477-4c8a-be70-634c1c9d523a] received
[2025-02-17 06:50:00,102: ERROR/MainProcess] Task fpl.tasks.fetch_fpl_data[a6c2b6a4-7477-4c8a-be70-634c1c9d523a] raised unexpected: ModuleNotFoundError("No module named 'requests'")
Traceback (most recent call last):
  File "/home/kevo/fpl_env/lib/python3.8/site-packages/celery/app/trace.py", line 453, in trace_task
    R = retval = fun(*args, **kwargs)
  File "/home/kevo/fpl_env/lib/python3.8/site-packages/celery/app/trace.py", line 736, in __protected_call__
    return self.run(*args, **kwargs)
  File "/mnt/c/Users/ADMIN/fpl_project/fpl/tasks.py", line 6, in fetch_fpl_data
    call_command("fetch_fpl_data")
  File "/home/kevo/fpl_env/lib/python3.8/site-packages/django/core/management/__init__.py", line 118, in call_command
    command = load_command_class(app_name, command_name)
  File "/home/kevo/fpl_env/lib/python3.8/site-packages/django/core/management/__init__.py", line 48, in load_command_class
    module = import_module("%s.management.commands.%s" % (app_name, name))
  File "/usr/lib/python3.8/importlib/__init__.py", line 127, in import_module
    return _bootstrap._gcd_import(name[level:], package, level)
  File "<frozen importlib._bootstrap>", line 1014, in _gcd_import
  File "<frozen importlib._bootstrap>", line 991, in _find_and_load
  File "<frozen importlib._bootstrap>", line 975, in _find_and_load_unlocked
  File "<frozen importlib._bootstrap>", line 671, in _load_unlocked
  File "<frozen importlib._bootstrap_external>", line 848, in exec_module
  File "<frozen importlib._bootstrap>", line 219, in _call_with_frames_removed
  File "/mnt/c/Users/ADMIN/fpl_project/fpl/management/commands/fetch_fpl_data.py", line 1, in <module>
    import requests
ModuleNotFoundError: No module named 'requests'
[2025-02-17 06:50:40,312: INFO/MainProcess] sync with worker1@DESKTOP-2OLMUVD

worker: Warm shutdown (MainProcess)
